2024-06-12 11:59:20,830 ERROR scheduler Exception in Enqueue Events for Site test.connectkare.in
Traceback (most recent call last):
  File "apps/frappe/frappe/utils/scheduler.py", line 71, in enqueue_events_for_site
    if is_scheduler_inactive():
  File "apps/frappe/frappe/utils/scheduler.py", line 110, in is_scheduler_inactive
    if is_scheduler_disabled(verbose=verbose):
  File "apps/frappe/frappe/utils/scheduler.py", line 123, in is_scheduler_disabled
    frappe.db.get_single_value("System Settings", "enable_scheduler")
  File "apps/frappe/frappe/database/database.py", line 776, in get_single_value
    df = frappe.get_meta(doctype).get_field(fieldname)
  File "apps/frappe/frappe/__init__.py", line 1211, in get_meta
    return frappe.model.meta.get_meta(doctype, cached=cached)
  File "apps/frappe/frappe/model/meta.py", line 65, in get_meta
    meta = Meta(doctype)
  File "apps/frappe/frappe/model/meta.py", line 117, in __init__
    super().__init__("DocType", doctype)
  File "apps/frappe/frappe/model/document.py", line 106, in __init__
    self.load_from_db()
  File "apps/frappe/frappe/model/meta.py", line 123, in load_from_db
    super().load_from_db()
  File "apps/frappe/frappe/model/document.py", line 149, in load_from_db
    frappe.throw(
  File "apps/frappe/frappe/__init__.py", line 525, in throw
    msgprint(
  File "apps/frappe/frappe/__init__.py", line 493, in msgprint
    _raise_exception()
  File "apps/frappe/frappe/__init__.py", line 442, in _raise_exception
    raise raise_exception(msg)
frappe.exceptions.DoesNotExistError: DocType System Settings not found

2024-06-12 18:36:17,403 ERROR scheduler Exception in Enqueue Events for Site test.connectkare.in
Traceback (most recent call last):
  File "apps/frappe/frappe/utils/scheduler.py", line 71, in enqueue_events_for_site
    if is_scheduler_inactive():
  File "apps/frappe/frappe/utils/scheduler.py", line 110, in is_scheduler_inactive
    if is_scheduler_disabled(verbose=verbose):
  File "apps/frappe/frappe/utils/scheduler.py", line 123, in is_scheduler_disabled
    frappe.db.get_single_value("System Settings", "enable_scheduler")
  File "apps/frappe/frappe/database/database.py", line 773, in get_single_value
    ).run()
  File "apps/frappe/frappe/query_builder/utils.py", line 76, in execute_query
    return frappe.db.sql(query, params, *args, **kwargs)  # nosemgrep
  File "apps/frappe/frappe/database/database.py", line 200, in sql
    self.connect()
  File "apps/frappe/frappe/database/database.py", line 114, in connect
    self._conn = self.get_connection()
  File "apps/frappe/frappe/database/mariadb/database.py", line 98, in get_connection
    conn = self._get_connection()
  File "apps/frappe/frappe/database/mariadb/database.py", line 104, in _get_connection
    return self.create_connection()
  File "apps/frappe/frappe/database/mariadb/database.py", line 107, in create_connection
    return pymysql.connect(**self.get_connection_settings())
  File "env/lib/python3.10/site-packages/pymysql/connections.py", line 352, in __init__
    self.connect()
  File "env/lib/python3.10/site-packages/pymysql/connections.py", line 636, in connect
    self._request_authentication()
  File "env/lib/python3.10/site-packages/pymysql/connections.py", line 911, in _request_authentication
    auth_packet = self._read_packet()
  File "env/lib/python3.10/site-packages/pymysql/connections.py", line 729, in _read_packet
    packet.raise_for_error()
  File "env/lib/python3.10/site-packages/pymysql/protocol.py", line 221, in raise_for_error
    err.raise_mysql_exception(self._data)
  File "env/lib/python3.10/site-packages/pymysql/err.py", line 143, in raise_mysql_exception
    raise errorclass(errno, errval)
pymysql.err.OperationalError: (1698, "Access denied for user '_039cc45dd718bebf'@'localhost'")

2024-06-12 18:39:18,111 ERROR scheduler Exception in Enqueue Events for Site test.connectkare.in
Traceback (most recent call last):
  File "apps/frappe/frappe/utils/scheduler.py", line 71, in enqueue_events_for_site
    if is_scheduler_inactive():
  File "apps/frappe/frappe/utils/scheduler.py", line 110, in is_scheduler_inactive
    if is_scheduler_disabled(verbose=verbose):
  File "apps/frappe/frappe/utils/scheduler.py", line 123, in is_scheduler_disabled
    frappe.db.get_single_value("System Settings", "enable_scheduler")
  File "apps/frappe/frappe/database/database.py", line 773, in get_single_value
    ).run()
  File "apps/frappe/frappe/query_builder/utils.py", line 76, in execute_query
    return frappe.db.sql(query, params, *args, **kwargs)  # nosemgrep
  File "apps/frappe/frappe/database/database.py", line 219, in sql
    self._cursor.execute(query, values)
  File "env/lib/python3.10/site-packages/pymysql/cursors.py", line 158, in execute
    result = self._query(query)
  File "env/lib/python3.10/site-packages/pymysql/cursors.py", line 325, in _query
    conn.query(q)
  File "env/lib/python3.10/site-packages/pymysql/connections.py", line 549, in query
    self._affected_rows = self._read_query_result(unbuffered=unbuffered)
  File "env/lib/python3.10/site-packages/pymysql/connections.py", line 779, in _read_query_result
    result.read()
  File "env/lib/python3.10/site-packages/pymysql/connections.py", line 1157, in read
    first_packet = self.connection._read_packet()
  File "env/lib/python3.10/site-packages/pymysql/connections.py", line 729, in _read_packet
    packet.raise_for_error()
  File "env/lib/python3.10/site-packages/pymysql/protocol.py", line 221, in raise_for_error
    err.raise_mysql_exception(self._data)
  File "env/lib/python3.10/site-packages/pymysql/err.py", line 143, in raise_mysql_exception
    raise errorclass(errno, errval)
pymysql.err.ProgrammingError: (1146, "Table '_d026d30d85988375.tabSingles' doesn't exist")

