2024-06-14 10:56:19,669 ERROR scheduler Exception in Enqueue Events for Site ssd.edofoxerp.com
Traceback (most recent call last):
  File "apps/frappe/frappe/utils/caching.py", line 55, in wrapper
    return frappe.local.request_cache[func][args_key]
KeyError: 5740354900026072187

During handling of the above exception, another exception occurred:

Traceback (most recent call last):
  File "apps/frappe/frappe/utils/caching.py", line 55, in wrapper
    return frappe.local.request_cache[func][args_key]
KeyError: -2601554533826868630

During handling of the above exception, another exception occurred:

Traceback (most recent call last):
  File "apps/frappe/frappe/utils/scheduler.py", line 71, in enqueue_events_for_site
    if is_scheduler_inactive():
  File "apps/frappe/frappe/utils/scheduler.py", line 110, in is_scheduler_inactive
    if is_scheduler_disabled(verbose=verbose):
  File "apps/frappe/frappe/utils/scheduler.py", line 123, in is_scheduler_disabled
    frappe.db.get_single_value("System Settings", "enable_scheduler")
  File "apps/frappe/frappe/database/database.py", line 769, in get_single_value
    val = frappe.qb.engine.get_query(
  File "apps/frappe/frappe/database/query.py", line 515, in get_query
    criterion = self.build_conditions(table, filters, **kwargs)
  File "apps/frappe/frappe/database/query.py", line 371, in build_conditions
    criterion = self.dict_query(filters=filters, table=table, **kwargs)
  File "apps/frappe/frappe/database/query.py", line 330, in dict_query
    _operator = self.OPERATOR_MAP["="]
  File "/usr/lib/python3.10/functools.py", line 981, in __get__
    val = self.func(instance)
  File "apps/frappe/frappe/database/query.py", line 196, in OPERATOR_MAP
    if frappe.get_hooks("filters_config"):
  File "apps/frappe/frappe/__init__.py", line 1496, in get_hooks
    hooks = _dict(_load_app_hooks())
  File "apps/frappe/frappe/utils/caching.py", line 57, in wrapper
    return_val = func(*args, **kwargs)
  File "apps/frappe/frappe/__init__.py", line 1461, in _load_app_hooks
    apps = [app_name] if app_name else get_installed_apps(_ensure_on_bench=True)
  File "apps/frappe/frappe/utils/caching.py", line 57, in wrapper
    return_val = func(*args, **kwargs)
  File "apps/frappe/frappe/__init__.py", line 1417, in get_installed_apps
    installed = json.loads(db.get_global("installed_apps") or "[]")
  File "apps/frappe/frappe/database/database.py", line 961, in get_global
    return self.get_default(key, user)
  File "apps/frappe/frappe/database/database.py", line 965, in get_default
    d = self.get_defaults(key, parent)
  File "apps/frappe/frappe/database/database.py", line 981, in get_defaults
    defaults = frappe.defaults.get_defaults_for(parent)
  File "apps/frappe/frappe/defaults.py", line 239, in get_defaults_for
    frappe.qb.from_(table)
  File "apps/frappe/frappe/query_builder/utils.py", line 76, in execute_query
    return frappe.db.sql(query, params, *args, **kwargs)  # nosemgrep
  File "apps/frappe/frappe/database/database.py", line 200, in sql
    self.connect()
  File "apps/frappe/frappe/database/database.py", line 114, in connect
    self._conn = self.get_connection()
  File "apps/frappe/frappe/database/mariadb/database.py", line 98, in get_connection
    conn = self._get_connection()
  File "apps/frappe/frappe/database/mariadb/database.py", line 104, in _get_connection
    return self.create_connection()
  File "apps/frappe/frappe/database/mariadb/database.py", line 107, in create_connection
    return pymysql.connect(**self.get_connection_settings())
  File "env/lib/python3.10/site-packages/pymysql/connections.py", line 352, in __init__
    self.connect()
  File "env/lib/python3.10/site-packages/pymysql/connections.py", line 636, in connect
    self._request_authentication()
  File "env/lib/python3.10/site-packages/pymysql/connections.py", line 911, in _request_authentication
    auth_packet = self._read_packet()
  File "env/lib/python3.10/site-packages/pymysql/connections.py", line 729, in _read_packet
    packet.raise_for_error()
  File "env/lib/python3.10/site-packages/pymysql/protocol.py", line 221, in raise_for_error
    err.raise_mysql_exception(self._data)
  File "env/lib/python3.10/site-packages/pymysql/err.py", line 143, in raise_mysql_exception
    raise errorclass(errno, errval)
pymysql.err.OperationalError: (1698, "Access denied for user '_039cc45dd718bebf'@'localhost'")

2024-06-14 10:57:19,914 ERROR scheduler Exception in Enqueue Events for Site ssd.edofoxerp.com
Traceback (most recent call last):
  File "apps/frappe/frappe/utils/caching.py", line 55, in wrapper
    return frappe.local.request_cache[func][args_key]
KeyError: 5740354900026072187

During handling of the above exception, another exception occurred:

Traceback (most recent call last):
  File "apps/frappe/frappe/utils/caching.py", line 55, in wrapper
    return frappe.local.request_cache[func][args_key]
KeyError: -2601554533826868630

During handling of the above exception, another exception occurred:

Traceback (most recent call last):
  File "apps/frappe/frappe/utils/scheduler.py", line 71, in enqueue_events_for_site
    if is_scheduler_inactive():
  File "apps/frappe/frappe/utils/scheduler.py", line 110, in is_scheduler_inactive
    if is_scheduler_disabled(verbose=verbose):
  File "apps/frappe/frappe/utils/scheduler.py", line 123, in is_scheduler_disabled
    frappe.db.get_single_value("System Settings", "enable_scheduler")
  File "apps/frappe/frappe/database/database.py", line 769, in get_single_value
    val = frappe.qb.engine.get_query(
  File "apps/frappe/frappe/database/query.py", line 515, in get_query
    criterion = self.build_conditions(table, filters, **kwargs)
  File "apps/frappe/frappe/database/query.py", line 371, in build_conditions
    criterion = self.dict_query(filters=filters, table=table, **kwargs)
  File "apps/frappe/frappe/database/query.py", line 330, in dict_query
    _operator = self.OPERATOR_MAP["="]
  File "/usr/lib/python3.10/functools.py", line 981, in __get__
    val = self.func(instance)
  File "apps/frappe/frappe/database/query.py", line 196, in OPERATOR_MAP
    if frappe.get_hooks("filters_config"):
  File "apps/frappe/frappe/__init__.py", line 1496, in get_hooks
    hooks = _dict(_load_app_hooks())
  File "apps/frappe/frappe/utils/caching.py", line 57, in wrapper
    return_val = func(*args, **kwargs)
  File "apps/frappe/frappe/__init__.py", line 1461, in _load_app_hooks
    apps = [app_name] if app_name else get_installed_apps(_ensure_on_bench=True)
  File "apps/frappe/frappe/utils/caching.py", line 57, in wrapper
    return_val = func(*args, **kwargs)
  File "apps/frappe/frappe/__init__.py", line 1417, in get_installed_apps
    installed = json.loads(db.get_global("installed_apps") or "[]")
  File "apps/frappe/frappe/database/database.py", line 961, in get_global
    return self.get_default(key, user)
  File "apps/frappe/frappe/database/database.py", line 965, in get_default
    d = self.get_defaults(key, parent)
  File "apps/frappe/frappe/database/database.py", line 981, in get_defaults
    defaults = frappe.defaults.get_defaults_for(parent)
  File "apps/frappe/frappe/defaults.py", line 239, in get_defaults_for
    frappe.qb.from_(table)
  File "apps/frappe/frappe/query_builder/utils.py", line 76, in execute_query
    return frappe.db.sql(query, params, *args, **kwargs)  # nosemgrep
  File "apps/frappe/frappe/database/database.py", line 200, in sql
    self.connect()
  File "apps/frappe/frappe/database/database.py", line 114, in connect
    self._conn = self.get_connection()
  File "apps/frappe/frappe/database/mariadb/database.py", line 98, in get_connection
    conn = self._get_connection()
  File "apps/frappe/frappe/database/mariadb/database.py", line 104, in _get_connection
    return self.create_connection()
  File "apps/frappe/frappe/database/mariadb/database.py", line 107, in create_connection
    return pymysql.connect(**self.get_connection_settings())
  File "env/lib/python3.10/site-packages/pymysql/connections.py", line 352, in __init__
    self.connect()
  File "env/lib/python3.10/site-packages/pymysql/connections.py", line 636, in connect
    self._request_authentication()
  File "env/lib/python3.10/site-packages/pymysql/connections.py", line 911, in _request_authentication
    auth_packet = self._read_packet()
  File "env/lib/python3.10/site-packages/pymysql/connections.py", line 729, in _read_packet
    packet.raise_for_error()
  File "env/lib/python3.10/site-packages/pymysql/protocol.py", line 221, in raise_for_error
    err.raise_mysql_exception(self._data)
  File "env/lib/python3.10/site-packages/pymysql/err.py", line 143, in raise_mysql_exception
    raise errorclass(errno, errval)
pymysql.err.OperationalError: (1698, "Access denied for user '_039cc45dd718bebf'@'localhost'")

2024-06-14 10:58:20,157 ERROR scheduler Exception in Enqueue Events for Site ssd.edofoxerp.com
Traceback (most recent call last):
  File "apps/frappe/frappe/utils/caching.py", line 55, in wrapper
    return frappe.local.request_cache[func][args_key]
KeyError: 5740354900026072187

During handling of the above exception, another exception occurred:

Traceback (most recent call last):
  File "apps/frappe/frappe/utils/caching.py", line 55, in wrapper
    return frappe.local.request_cache[func][args_key]
KeyError: -2601554533826868630

During handling of the above exception, another exception occurred:

Traceback (most recent call last):
  File "apps/frappe/frappe/utils/scheduler.py", line 71, in enqueue_events_for_site
    if is_scheduler_inactive():
  File "apps/frappe/frappe/utils/scheduler.py", line 110, in is_scheduler_inactive
    if is_scheduler_disabled(verbose=verbose):
  File "apps/frappe/frappe/utils/scheduler.py", line 123, in is_scheduler_disabled
    frappe.db.get_single_value("System Settings", "enable_scheduler")
  File "apps/frappe/frappe/database/database.py", line 769, in get_single_value
    val = frappe.qb.engine.get_query(
  File "apps/frappe/frappe/database/query.py", line 515, in get_query
    criterion = self.build_conditions(table, filters, **kwargs)
  File "apps/frappe/frappe/database/query.py", line 371, in build_conditions
    criterion = self.dict_query(filters=filters, table=table, **kwargs)
  File "apps/frappe/frappe/database/query.py", line 330, in dict_query
    _operator = self.OPERATOR_MAP["="]
  File "/usr/lib/python3.10/functools.py", line 981, in __get__
    val = self.func(instance)
  File "apps/frappe/frappe/database/query.py", line 196, in OPERATOR_MAP
    if frappe.get_hooks("filters_config"):
  File "apps/frappe/frappe/__init__.py", line 1496, in get_hooks
    hooks = _dict(_load_app_hooks())
  File "apps/frappe/frappe/utils/caching.py", line 57, in wrapper
    return_val = func(*args, **kwargs)
  File "apps/frappe/frappe/__init__.py", line 1461, in _load_app_hooks
    apps = [app_name] if app_name else get_installed_apps(_ensure_on_bench=True)
  File "apps/frappe/frappe/utils/caching.py", line 57, in wrapper
    return_val = func(*args, **kwargs)
  File "apps/frappe/frappe/__init__.py", line 1417, in get_installed_apps
    installed = json.loads(db.get_global("installed_apps") or "[]")
  File "apps/frappe/frappe/database/database.py", line 961, in get_global
    return self.get_default(key, user)
  File "apps/frappe/frappe/database/database.py", line 965, in get_default
    d = self.get_defaults(key, parent)
  File "apps/frappe/frappe/database/database.py", line 981, in get_defaults
    defaults = frappe.defaults.get_defaults_for(parent)
  File "apps/frappe/frappe/defaults.py", line 239, in get_defaults_for
    frappe.qb.from_(table)
  File "apps/frappe/frappe/query_builder/utils.py", line 76, in execute_query
    return frappe.db.sql(query, params, *args, **kwargs)  # nosemgrep
  File "apps/frappe/frappe/database/database.py", line 200, in sql
    self.connect()
  File "apps/frappe/frappe/database/database.py", line 114, in connect
    self._conn = self.get_connection()
  File "apps/frappe/frappe/database/mariadb/database.py", line 98, in get_connection
    conn = self._get_connection()
  File "apps/frappe/frappe/database/mariadb/database.py", line 104, in _get_connection
    return self.create_connection()
  File "apps/frappe/frappe/database/mariadb/database.py", line 107, in create_connection
    return pymysql.connect(**self.get_connection_settings())
  File "env/lib/python3.10/site-packages/pymysql/connections.py", line 352, in __init__
    self.connect()
  File "env/lib/python3.10/site-packages/pymysql/connections.py", line 636, in connect
    self._request_authentication()
  File "env/lib/python3.10/site-packages/pymysql/connections.py", line 911, in _request_authentication
    auth_packet = self._read_packet()
  File "env/lib/python3.10/site-packages/pymysql/connections.py", line 729, in _read_packet
    packet.raise_for_error()
  File "env/lib/python3.10/site-packages/pymysql/protocol.py", line 221, in raise_for_error
    err.raise_mysql_exception(self._data)
  File "env/lib/python3.10/site-packages/pymysql/err.py", line 143, in raise_mysql_exception
    raise errorclass(errno, errval)
pymysql.err.OperationalError: (1698, "Access denied for user '_039cc45dd718bebf'@'localhost'")

2024-06-14 10:59:20,386 ERROR scheduler Exception in Enqueue Events for Site ssd.edofoxerp.com
Traceback (most recent call last):
  File "apps/frappe/frappe/utils/caching.py", line 55, in wrapper
    return frappe.local.request_cache[func][args_key]
KeyError: 5740354900026072187

During handling of the above exception, another exception occurred:

Traceback (most recent call last):
  File "apps/frappe/frappe/utils/caching.py", line 55, in wrapper
    return frappe.local.request_cache[func][args_key]
KeyError: -2601554533826868630

During handling of the above exception, another exception occurred:

Traceback (most recent call last):
  File "apps/frappe/frappe/utils/scheduler.py", line 71, in enqueue_events_for_site
    if is_scheduler_inactive():
  File "apps/frappe/frappe/utils/scheduler.py", line 110, in is_scheduler_inactive
    if is_scheduler_disabled(verbose=verbose):
  File "apps/frappe/frappe/utils/scheduler.py", line 123, in is_scheduler_disabled
    frappe.db.get_single_value("System Settings", "enable_scheduler")
  File "apps/frappe/frappe/database/database.py", line 769, in get_single_value
    val = frappe.qb.engine.get_query(
  File "apps/frappe/frappe/database/query.py", line 515, in get_query
    criterion = self.build_conditions(table, filters, **kwargs)
  File "apps/frappe/frappe/database/query.py", line 371, in build_conditions
    criterion = self.dict_query(filters=filters, table=table, **kwargs)
  File "apps/frappe/frappe/database/query.py", line 330, in dict_query
    _operator = self.OPERATOR_MAP["="]
  File "/usr/lib/python3.10/functools.py", line 981, in __get__
    val = self.func(instance)
  File "apps/frappe/frappe/database/query.py", line 196, in OPERATOR_MAP
    if frappe.get_hooks("filters_config"):
  File "apps/frappe/frappe/__init__.py", line 1496, in get_hooks
    hooks = _dict(_load_app_hooks())
  File "apps/frappe/frappe/utils/caching.py", line 57, in wrapper
    return_val = func(*args, **kwargs)
  File "apps/frappe/frappe/__init__.py", line 1461, in _load_app_hooks
    apps = [app_name] if app_name else get_installed_apps(_ensure_on_bench=True)
  File "apps/frappe/frappe/utils/caching.py", line 57, in wrapper
    return_val = func(*args, **kwargs)
  File "apps/frappe/frappe/__init__.py", line 1417, in get_installed_apps
    installed = json.loads(db.get_global("installed_apps") or "[]")
  File "apps/frappe/frappe/database/database.py", line 961, in get_global
    return self.get_default(key, user)
  File "apps/frappe/frappe/database/database.py", line 965, in get_default
    d = self.get_defaults(key, parent)
  File "apps/frappe/frappe/database/database.py", line 981, in get_defaults
    defaults = frappe.defaults.get_defaults_for(parent)
  File "apps/frappe/frappe/defaults.py", line 239, in get_defaults_for
    frappe.qb.from_(table)
  File "apps/frappe/frappe/query_builder/utils.py", line 76, in execute_query
    return frappe.db.sql(query, params, *args, **kwargs)  # nosemgrep
  File "apps/frappe/frappe/database/database.py", line 200, in sql
    self.connect()
  File "apps/frappe/frappe/database/database.py", line 114, in connect
    self._conn = self.get_connection()
  File "apps/frappe/frappe/database/mariadb/database.py", line 98, in get_connection
    conn = self._get_connection()
  File "apps/frappe/frappe/database/mariadb/database.py", line 104, in _get_connection
    return self.create_connection()
  File "apps/frappe/frappe/database/mariadb/database.py", line 107, in create_connection
    return pymysql.connect(**self.get_connection_settings())
  File "env/lib/python3.10/site-packages/pymysql/connections.py", line 352, in __init__
    self.connect()
  File "env/lib/python3.10/site-packages/pymysql/connections.py", line 636, in connect
    self._request_authentication()
  File "env/lib/python3.10/site-packages/pymysql/connections.py", line 911, in _request_authentication
    auth_packet = self._read_packet()
  File "env/lib/python3.10/site-packages/pymysql/connections.py", line 729, in _read_packet
    packet.raise_for_error()
  File "env/lib/python3.10/site-packages/pymysql/protocol.py", line 221, in raise_for_error
    err.raise_mysql_exception(self._data)
  File "env/lib/python3.10/site-packages/pymysql/err.py", line 143, in raise_mysql_exception
    raise errorclass(errno, errval)
pymysql.err.OperationalError: (1698, "Access denied for user '_039cc45dd718bebf'@'localhost'")

2024-06-14 11:00:21,284 ERROR scheduler Exception in Enqueue Events for Site ssd.edofoxerp.com
Traceback (most recent call last):
  File "apps/frappe/frappe/utils/caching.py", line 55, in wrapper
    return frappe.local.request_cache[func][args_key]
KeyError: 5740354900026072187

During handling of the above exception, another exception occurred:

Traceback (most recent call last):
  File "apps/frappe/frappe/utils/caching.py", line 55, in wrapper
    return frappe.local.request_cache[func][args_key]
KeyError: -2601554533826868630

During handling of the above exception, another exception occurred:

Traceback (most recent call last):
  File "apps/frappe/frappe/utils/scheduler.py", line 71, in enqueue_events_for_site
    if is_scheduler_inactive():
  File "apps/frappe/frappe/utils/scheduler.py", line 110, in is_scheduler_inactive
    if is_scheduler_disabled(verbose=verbose):
  File "apps/frappe/frappe/utils/scheduler.py", line 123, in is_scheduler_disabled
    frappe.db.get_single_value("System Settings", "enable_scheduler")
  File "apps/frappe/frappe/database/database.py", line 769, in get_single_value
    val = frappe.qb.engine.get_query(
  File "apps/frappe/frappe/database/query.py", line 515, in get_query
    criterion = self.build_conditions(table, filters, **kwargs)
  File "apps/frappe/frappe/database/query.py", line 371, in build_conditions
    criterion = self.dict_query(filters=filters, table=table, **kwargs)
  File "apps/frappe/frappe/database/query.py", line 330, in dict_query
    _operator = self.OPERATOR_MAP["="]
  File "/usr/lib/python3.10/functools.py", line 981, in __get__
    val = self.func(instance)
  File "apps/frappe/frappe/database/query.py", line 196, in OPERATOR_MAP
    if frappe.get_hooks("filters_config"):
  File "apps/frappe/frappe/__init__.py", line 1496, in get_hooks
    hooks = _dict(_load_app_hooks())
  File "apps/frappe/frappe/utils/caching.py", line 57, in wrapper
    return_val = func(*args, **kwargs)
  File "apps/frappe/frappe/__init__.py", line 1461, in _load_app_hooks
    apps = [app_name] if app_name else get_installed_apps(_ensure_on_bench=True)
  File "apps/frappe/frappe/utils/caching.py", line 57, in wrapper
    return_val = func(*args, **kwargs)
  File "apps/frappe/frappe/__init__.py", line 1417, in get_installed_apps
    installed = json.loads(db.get_global("installed_apps") or "[]")
  File "apps/frappe/frappe/database/database.py", line 961, in get_global
    return self.get_default(key, user)
  File "apps/frappe/frappe/database/database.py", line 965, in get_default
    d = self.get_defaults(key, parent)
  File "apps/frappe/frappe/database/database.py", line 981, in get_defaults
    defaults = frappe.defaults.get_defaults_for(parent)
  File "apps/frappe/frappe/defaults.py", line 239, in get_defaults_for
    frappe.qb.from_(table)
  File "apps/frappe/frappe/query_builder/utils.py", line 76, in execute_query
    return frappe.db.sql(query, params, *args, **kwargs)  # nosemgrep
  File "apps/frappe/frappe/database/database.py", line 200, in sql
    self.connect()
  File "apps/frappe/frappe/database/database.py", line 114, in connect
    self._conn = self.get_connection()
  File "apps/frappe/frappe/database/mariadb/database.py", line 98, in get_connection
    conn = self._get_connection()
  File "apps/frappe/frappe/database/mariadb/database.py", line 104, in _get_connection
    return self.create_connection()
  File "apps/frappe/frappe/database/mariadb/database.py", line 107, in create_connection
    return pymysql.connect(**self.get_connection_settings())
  File "env/lib/python3.10/site-packages/pymysql/connections.py", line 352, in __init__
    self.connect()
  File "env/lib/python3.10/site-packages/pymysql/connections.py", line 636, in connect
    self._request_authentication()
  File "env/lib/python3.10/site-packages/pymysql/connections.py", line 911, in _request_authentication
    auth_packet = self._read_packet()
  File "env/lib/python3.10/site-packages/pymysql/connections.py", line 729, in _read_packet
    packet.raise_for_error()
  File "env/lib/python3.10/site-packages/pymysql/protocol.py", line 221, in raise_for_error
    err.raise_mysql_exception(self._data)
  File "env/lib/python3.10/site-packages/pymysql/err.py", line 143, in raise_mysql_exception
    raise errorclass(errno, errval)
pymysql.err.OperationalError: (1698, "Access denied for user '_039cc45dd718bebf'@'localhost'")

2024-06-14 11:01:21,510 ERROR scheduler Exception in Enqueue Events for Site ssd.edofoxerp.com
Traceback (most recent call last):
  File "apps/frappe/frappe/utils/caching.py", line 55, in wrapper
    return frappe.local.request_cache[func][args_key]
KeyError: 5740354900026072187

During handling of the above exception, another exception occurred:

Traceback (most recent call last):
  File "apps/frappe/frappe/utils/caching.py", line 55, in wrapper
    return frappe.local.request_cache[func][args_key]
KeyError: -2601554533826868630

During handling of the above exception, another exception occurred:

Traceback (most recent call last):
  File "apps/frappe/frappe/utils/scheduler.py", line 71, in enqueue_events_for_site
    if is_scheduler_inactive():
  File "apps/frappe/frappe/utils/scheduler.py", line 110, in is_scheduler_inactive
    if is_scheduler_disabled(verbose=verbose):
  File "apps/frappe/frappe/utils/scheduler.py", line 123, in is_scheduler_disabled
    frappe.db.get_single_value("System Settings", "enable_scheduler")
  File "apps/frappe/frappe/database/database.py", line 769, in get_single_value
    val = frappe.qb.engine.get_query(
  File "apps/frappe/frappe/database/query.py", line 515, in get_query
    criterion = self.build_conditions(table, filters, **kwargs)
  File "apps/frappe/frappe/database/query.py", line 371, in build_conditions
    criterion = self.dict_query(filters=filters, table=table, **kwargs)
  File "apps/frappe/frappe/database/query.py", line 330, in dict_query
    _operator = self.OPERATOR_MAP["="]
  File "/usr/lib/python3.10/functools.py", line 981, in __get__
    val = self.func(instance)
  File "apps/frappe/frappe/database/query.py", line 196, in OPERATOR_MAP
    if frappe.get_hooks("filters_config"):
  File "apps/frappe/frappe/__init__.py", line 1496, in get_hooks
    hooks = _dict(_load_app_hooks())
  File "apps/frappe/frappe/utils/caching.py", line 57, in wrapper
    return_val = func(*args, **kwargs)
  File "apps/frappe/frappe/__init__.py", line 1461, in _load_app_hooks
    apps = [app_name] if app_name else get_installed_apps(_ensure_on_bench=True)
  File "apps/frappe/frappe/utils/caching.py", line 57, in wrapper
    return_val = func(*args, **kwargs)
  File "apps/frappe/frappe/__init__.py", line 1417, in get_installed_apps
    installed = json.loads(db.get_global("installed_apps") or "[]")
  File "apps/frappe/frappe/database/database.py", line 961, in get_global
    return self.get_default(key, user)
  File "apps/frappe/frappe/database/database.py", line 965, in get_default
    d = self.get_defaults(key, parent)
  File "apps/frappe/frappe/database/database.py", line 981, in get_defaults
    defaults = frappe.defaults.get_defaults_for(parent)
  File "apps/frappe/frappe/defaults.py", line 239, in get_defaults_for
    frappe.qb.from_(table)
  File "apps/frappe/frappe/query_builder/utils.py", line 76, in execute_query
    return frappe.db.sql(query, params, *args, **kwargs)  # nosemgrep
  File "apps/frappe/frappe/database/database.py", line 200, in sql
    self.connect()
  File "apps/frappe/frappe/database/database.py", line 114, in connect
    self._conn = self.get_connection()
  File "apps/frappe/frappe/database/mariadb/database.py", line 98, in get_connection
    conn = self._get_connection()
  File "apps/frappe/frappe/database/mariadb/database.py", line 104, in _get_connection
    return self.create_connection()
  File "apps/frappe/frappe/database/mariadb/database.py", line 107, in create_connection
    return pymysql.connect(**self.get_connection_settings())
  File "env/lib/python3.10/site-packages/pymysql/connections.py", line 352, in __init__
    self.connect()
  File "env/lib/python3.10/site-packages/pymysql/connections.py", line 636, in connect
    self._request_authentication()
  File "env/lib/python3.10/site-packages/pymysql/connections.py", line 911, in _request_authentication
    auth_packet = self._read_packet()
  File "env/lib/python3.10/site-packages/pymysql/connections.py", line 729, in _read_packet
    packet.raise_for_error()
  File "env/lib/python3.10/site-packages/pymysql/protocol.py", line 221, in raise_for_error
    err.raise_mysql_exception(self._data)
  File "env/lib/python3.10/site-packages/pymysql/err.py", line 143, in raise_mysql_exception
    raise errorclass(errno, errval)
pymysql.err.OperationalError: (1698, "Access denied for user '_039cc45dd718bebf'@'localhost'")

2024-06-14 11:02:21,715 ERROR scheduler Exception in Enqueue Events for Site ssd.edofoxerp.com
Traceback (most recent call last):
  File "apps/frappe/frappe/utils/caching.py", line 55, in wrapper
    return frappe.local.request_cache[func][args_key]
KeyError: 5740354900026072187

During handling of the above exception, another exception occurred:

Traceback (most recent call last):
  File "apps/frappe/frappe/utils/caching.py", line 55, in wrapper
    return frappe.local.request_cache[func][args_key]
KeyError: -2601554533826868630

During handling of the above exception, another exception occurred:

Traceback (most recent call last):
  File "apps/frappe/frappe/utils/scheduler.py", line 71, in enqueue_events_for_site
    if is_scheduler_inactive():
  File "apps/frappe/frappe/utils/scheduler.py", line 110, in is_scheduler_inactive
    if is_scheduler_disabled(verbose=verbose):
  File "apps/frappe/frappe/utils/scheduler.py", line 123, in is_scheduler_disabled
    frappe.db.get_single_value("System Settings", "enable_scheduler")
  File "apps/frappe/frappe/database/database.py", line 769, in get_single_value
    val = frappe.qb.engine.get_query(
  File "apps/frappe/frappe/database/query.py", line 515, in get_query
    criterion = self.build_conditions(table, filters, **kwargs)
  File "apps/frappe/frappe/database/query.py", line 371, in build_conditions
    criterion = self.dict_query(filters=filters, table=table, **kwargs)
  File "apps/frappe/frappe/database/query.py", line 330, in dict_query
    _operator = self.OPERATOR_MAP["="]
  File "/usr/lib/python3.10/functools.py", line 981, in __get__
    val = self.func(instance)
  File "apps/frappe/frappe/database/query.py", line 196, in OPERATOR_MAP
    if frappe.get_hooks("filters_config"):
  File "apps/frappe/frappe/__init__.py", line 1496, in get_hooks
    hooks = _dict(_load_app_hooks())
  File "apps/frappe/frappe/utils/caching.py", line 57, in wrapper
    return_val = func(*args, **kwargs)
  File "apps/frappe/frappe/__init__.py", line 1461, in _load_app_hooks
    apps = [app_name] if app_name else get_installed_apps(_ensure_on_bench=True)
  File "apps/frappe/frappe/utils/caching.py", line 57, in wrapper
    return_val = func(*args, **kwargs)
  File "apps/frappe/frappe/__init__.py", line 1417, in get_installed_apps
    installed = json.loads(db.get_global("installed_apps") or "[]")
  File "apps/frappe/frappe/database/database.py", line 961, in get_global
    return self.get_default(key, user)
  File "apps/frappe/frappe/database/database.py", line 965, in get_default
    d = self.get_defaults(key, parent)
  File "apps/frappe/frappe/database/database.py", line 981, in get_defaults
    defaults = frappe.defaults.get_defaults_for(parent)
  File "apps/frappe/frappe/defaults.py", line 239, in get_defaults_for
    frappe.qb.from_(table)
  File "apps/frappe/frappe/query_builder/utils.py", line 76, in execute_query
    return frappe.db.sql(query, params, *args, **kwargs)  # nosemgrep
  File "apps/frappe/frappe/database/database.py", line 200, in sql
    self.connect()
  File "apps/frappe/frappe/database/database.py", line 114, in connect
    self._conn = self.get_connection()
  File "apps/frappe/frappe/database/mariadb/database.py", line 98, in get_connection
    conn = self._get_connection()
  File "apps/frappe/frappe/database/mariadb/database.py", line 104, in _get_connection
    return self.create_connection()
  File "apps/frappe/frappe/database/mariadb/database.py", line 107, in create_connection
    return pymysql.connect(**self.get_connection_settings())
  File "env/lib/python3.10/site-packages/pymysql/connections.py", line 352, in __init__
    self.connect()
  File "env/lib/python3.10/site-packages/pymysql/connections.py", line 636, in connect
    self._request_authentication()
  File "env/lib/python3.10/site-packages/pymysql/connections.py", line 911, in _request_authentication
    auth_packet = self._read_packet()
  File "env/lib/python3.10/site-packages/pymysql/connections.py", line 729, in _read_packet
    packet.raise_for_error()
  File "env/lib/python3.10/site-packages/pymysql/protocol.py", line 221, in raise_for_error
    err.raise_mysql_exception(self._data)
  File "env/lib/python3.10/site-packages/pymysql/err.py", line 143, in raise_mysql_exception
    raise errorclass(errno, errval)
pymysql.err.OperationalError: (1698, "Access denied for user '_039cc45dd718bebf'@'localhost'")

2024-06-14 11:03:21,940 ERROR scheduler Exception in Enqueue Events for Site ssd.edofoxerp.com
Traceback (most recent call last):
  File "apps/frappe/frappe/utils/caching.py", line 55, in wrapper
    return frappe.local.request_cache[func][args_key]
KeyError: 5740354900026072187

During handling of the above exception, another exception occurred:

Traceback (most recent call last):
  File "apps/frappe/frappe/utils/caching.py", line 55, in wrapper
    return frappe.local.request_cache[func][args_key]
KeyError: -2601554533826868630

During handling of the above exception, another exception occurred:

Traceback (most recent call last):
  File "apps/frappe/frappe/utils/scheduler.py", line 71, in enqueue_events_for_site
    if is_scheduler_inactive():
  File "apps/frappe/frappe/utils/scheduler.py", line 110, in is_scheduler_inactive
    if is_scheduler_disabled(verbose=verbose):
  File "apps/frappe/frappe/utils/scheduler.py", line 123, in is_scheduler_disabled
    frappe.db.get_single_value("System Settings", "enable_scheduler")
  File "apps/frappe/frappe/database/database.py", line 769, in get_single_value
    val = frappe.qb.engine.get_query(
  File "apps/frappe/frappe/database/query.py", line 515, in get_query
    criterion = self.build_conditions(table, filters, **kwargs)
  File "apps/frappe/frappe/database/query.py", line 371, in build_conditions
    criterion = self.dict_query(filters=filters, table=table, **kwargs)
  File "apps/frappe/frappe/database/query.py", line 330, in dict_query
    _operator = self.OPERATOR_MAP["="]
  File "/usr/lib/python3.10/functools.py", line 981, in __get__
    val = self.func(instance)
  File "apps/frappe/frappe/database/query.py", line 196, in OPERATOR_MAP
    if frappe.get_hooks("filters_config"):
  File "apps/frappe/frappe/__init__.py", line 1496, in get_hooks
    hooks = _dict(_load_app_hooks())
  File "apps/frappe/frappe/utils/caching.py", line 57, in wrapper
    return_val = func(*args, **kwargs)
  File "apps/frappe/frappe/__init__.py", line 1461, in _load_app_hooks
    apps = [app_name] if app_name else get_installed_apps(_ensure_on_bench=True)
  File "apps/frappe/frappe/utils/caching.py", line 57, in wrapper
    return_val = func(*args, **kwargs)
  File "apps/frappe/frappe/__init__.py", line 1417, in get_installed_apps
    installed = json.loads(db.get_global("installed_apps") or "[]")
  File "apps/frappe/frappe/database/database.py", line 961, in get_global
    return self.get_default(key, user)
  File "apps/frappe/frappe/database/database.py", line 965, in get_default
    d = self.get_defaults(key, parent)
  File "apps/frappe/frappe/database/database.py", line 981, in get_defaults
    defaults = frappe.defaults.get_defaults_for(parent)
  File "apps/frappe/frappe/defaults.py", line 239, in get_defaults_for
    frappe.qb.from_(table)
  File "apps/frappe/frappe/query_builder/utils.py", line 76, in execute_query
    return frappe.db.sql(query, params, *args, **kwargs)  # nosemgrep
  File "apps/frappe/frappe/database/database.py", line 200, in sql
    self.connect()
  File "apps/frappe/frappe/database/database.py", line 114, in connect
    self._conn = self.get_connection()
  File "apps/frappe/frappe/database/mariadb/database.py", line 98, in get_connection
    conn = self._get_connection()
  File "apps/frappe/frappe/database/mariadb/database.py", line 104, in _get_connection
    return self.create_connection()
  File "apps/frappe/frappe/database/mariadb/database.py", line 107, in create_connection
    return pymysql.connect(**self.get_connection_settings())
  File "env/lib/python3.10/site-packages/pymysql/connections.py", line 352, in __init__
    self.connect()
  File "env/lib/python3.10/site-packages/pymysql/connections.py", line 636, in connect
    self._request_authentication()
  File "env/lib/python3.10/site-packages/pymysql/connections.py", line 911, in _request_authentication
    auth_packet = self._read_packet()
  File "env/lib/python3.10/site-packages/pymysql/connections.py", line 729, in _read_packet
    packet.raise_for_error()
  File "env/lib/python3.10/site-packages/pymysql/protocol.py", line 221, in raise_for_error
    err.raise_mysql_exception(self._data)
  File "env/lib/python3.10/site-packages/pymysql/err.py", line 143, in raise_mysql_exception
    raise errorclass(errno, errval)
pymysql.err.OperationalError: (1698, "Access denied for user '_039cc45dd718bebf'@'localhost'")

2024-06-14 11:04:22,248 ERROR scheduler Exception in Enqueue Events for Site ssd.edofoxerp.com
Traceback (most recent call last):
  File "apps/frappe/frappe/utils/caching.py", line 55, in wrapper
    return frappe.local.request_cache[func][args_key]
KeyError: 5740354900026072187

During handling of the above exception, another exception occurred:

Traceback (most recent call last):
  File "apps/frappe/frappe/utils/caching.py", line 55, in wrapper
    return frappe.local.request_cache[func][args_key]
KeyError: -2601554533826868630

During handling of the above exception, another exception occurred:

Traceback (most recent call last):
  File "apps/frappe/frappe/utils/scheduler.py", line 71, in enqueue_events_for_site
    if is_scheduler_inactive():
  File "apps/frappe/frappe/utils/scheduler.py", line 110, in is_scheduler_inactive
    if is_scheduler_disabled(verbose=verbose):
  File "apps/frappe/frappe/utils/scheduler.py", line 123, in is_scheduler_disabled
    frappe.db.get_single_value("System Settings", "enable_scheduler")
  File "apps/frappe/frappe/database/database.py", line 769, in get_single_value
    val = frappe.qb.engine.get_query(
  File "apps/frappe/frappe/database/query.py", line 515, in get_query
    criterion = self.build_conditions(table, filters, **kwargs)
  File "apps/frappe/frappe/database/query.py", line 371, in build_conditions
    criterion = self.dict_query(filters=filters, table=table, **kwargs)
  File "apps/frappe/frappe/database/query.py", line 330, in dict_query
    _operator = self.OPERATOR_MAP["="]
  File "/usr/lib/python3.10/functools.py", line 981, in __get__
    val = self.func(instance)
  File "apps/frappe/frappe/database/query.py", line 196, in OPERATOR_MAP
    if frappe.get_hooks("filters_config"):
  File "apps/frappe/frappe/__init__.py", line 1496, in get_hooks
    hooks = _dict(_load_app_hooks())
  File "apps/frappe/frappe/utils/caching.py", line 57, in wrapper
    return_val = func(*args, **kwargs)
  File "apps/frappe/frappe/__init__.py", line 1461, in _load_app_hooks
    apps = [app_name] if app_name else get_installed_apps(_ensure_on_bench=True)
  File "apps/frappe/frappe/utils/caching.py", line 57, in wrapper
    return_val = func(*args, **kwargs)
  File "apps/frappe/frappe/__init__.py", line 1417, in get_installed_apps
    installed = json.loads(db.get_global("installed_apps") or "[]")
  File "apps/frappe/frappe/database/database.py", line 961, in get_global
    return self.get_default(key, user)
  File "apps/frappe/frappe/database/database.py", line 965, in get_default
    d = self.get_defaults(key, parent)
  File "apps/frappe/frappe/database/database.py", line 981, in get_defaults
    defaults = frappe.defaults.get_defaults_for(parent)
  File "apps/frappe/frappe/defaults.py", line 239, in get_defaults_for
    frappe.qb.from_(table)
  File "apps/frappe/frappe/query_builder/utils.py", line 76, in execute_query
    return frappe.db.sql(query, params, *args, **kwargs)  # nosemgrep
  File "apps/frappe/frappe/database/database.py", line 200, in sql
    self.connect()
  File "apps/frappe/frappe/database/database.py", line 114, in connect
    self._conn = self.get_connection()
  File "apps/frappe/frappe/database/mariadb/database.py", line 98, in get_connection
    conn = self._get_connection()
  File "apps/frappe/frappe/database/mariadb/database.py", line 104, in _get_connection
    return self.create_connection()
  File "apps/frappe/frappe/database/mariadb/database.py", line 107, in create_connection
    return pymysql.connect(**self.get_connection_settings())
  File "env/lib/python3.10/site-packages/pymysql/connections.py", line 352, in __init__
    self.connect()
  File "env/lib/python3.10/site-packages/pymysql/connections.py", line 636, in connect
    self._request_authentication()
  File "env/lib/python3.10/site-packages/pymysql/connections.py", line 911, in _request_authentication
    auth_packet = self._read_packet()
  File "env/lib/python3.10/site-packages/pymysql/connections.py", line 729, in _read_packet
    packet.raise_for_error()
  File "env/lib/python3.10/site-packages/pymysql/protocol.py", line 221, in raise_for_error
    err.raise_mysql_exception(self._data)
  File "env/lib/python3.10/site-packages/pymysql/err.py", line 143, in raise_mysql_exception
    raise errorclass(errno, errval)
pymysql.err.OperationalError: (1698, "Access denied for user '_039cc45dd718bebf'@'localhost'")

2024-06-14 11:05:22,485 ERROR scheduler Exception in Enqueue Events for Site ssd.edofoxerp.com
Traceback (most recent call last):
  File "apps/frappe/frappe/utils/caching.py", line 55, in wrapper
    return frappe.local.request_cache[func][args_key]
KeyError: 5740354900026072187

During handling of the above exception, another exception occurred:

Traceback (most recent call last):
  File "apps/frappe/frappe/utils/caching.py", line 55, in wrapper
    return frappe.local.request_cache[func][args_key]
KeyError: -2601554533826868630

During handling of the above exception, another exception occurred:

Traceback (most recent call last):
  File "apps/frappe/frappe/utils/scheduler.py", line 71, in enqueue_events_for_site
    if is_scheduler_inactive():
  File "apps/frappe/frappe/utils/scheduler.py", line 110, in is_scheduler_inactive
    if is_scheduler_disabled(verbose=verbose):
  File "apps/frappe/frappe/utils/scheduler.py", line 123, in is_scheduler_disabled
    frappe.db.get_single_value("System Settings", "enable_scheduler")
  File "apps/frappe/frappe/database/database.py", line 769, in get_single_value
    val = frappe.qb.engine.get_query(
  File "apps/frappe/frappe/database/query.py", line 515, in get_query
    criterion = self.build_conditions(table, filters, **kwargs)
  File "apps/frappe/frappe/database/query.py", line 371, in build_conditions
    criterion = self.dict_query(filters=filters, table=table, **kwargs)
  File "apps/frappe/frappe/database/query.py", line 330, in dict_query
    _operator = self.OPERATOR_MAP["="]
  File "/usr/lib/python3.10/functools.py", line 981, in __get__
    val = self.func(instance)
  File "apps/frappe/frappe/database/query.py", line 196, in OPERATOR_MAP
    if frappe.get_hooks("filters_config"):
  File "apps/frappe/frappe/__init__.py", line 1496, in get_hooks
    hooks = _dict(_load_app_hooks())
  File "apps/frappe/frappe/utils/caching.py", line 57, in wrapper
    return_val = func(*args, **kwargs)
  File "apps/frappe/frappe/__init__.py", line 1461, in _load_app_hooks
    apps = [app_name] if app_name else get_installed_apps(_ensure_on_bench=True)
  File "apps/frappe/frappe/utils/caching.py", line 57, in wrapper
    return_val = func(*args, **kwargs)
  File "apps/frappe/frappe/__init__.py", line 1417, in get_installed_apps
    installed = json.loads(db.get_global("installed_apps") or "[]")
  File "apps/frappe/frappe/database/database.py", line 961, in get_global
    return self.get_default(key, user)
  File "apps/frappe/frappe/database/database.py", line 965, in get_default
    d = self.get_defaults(key, parent)
  File "apps/frappe/frappe/database/database.py", line 981, in get_defaults
    defaults = frappe.defaults.get_defaults_for(parent)
  File "apps/frappe/frappe/defaults.py", line 239, in get_defaults_for
    frappe.qb.from_(table)
  File "apps/frappe/frappe/query_builder/utils.py", line 76, in execute_query
    return frappe.db.sql(query, params, *args, **kwargs)  # nosemgrep
  File "apps/frappe/frappe/database/database.py", line 200, in sql
    self.connect()
  File "apps/frappe/frappe/database/database.py", line 114, in connect
    self._conn = self.get_connection()
  File "apps/frappe/frappe/database/mariadb/database.py", line 98, in get_connection
    conn = self._get_connection()
  File "apps/frappe/frappe/database/mariadb/database.py", line 104, in _get_connection
    return self.create_connection()
  File "apps/frappe/frappe/database/mariadb/database.py", line 107, in create_connection
    return pymysql.connect(**self.get_connection_settings())
  File "env/lib/python3.10/site-packages/pymysql/connections.py", line 352, in __init__
    self.connect()
  File "env/lib/python3.10/site-packages/pymysql/connections.py", line 636, in connect
    self._request_authentication()
  File "env/lib/python3.10/site-packages/pymysql/connections.py", line 911, in _request_authentication
    auth_packet = self._read_packet()
  File "env/lib/python3.10/site-packages/pymysql/connections.py", line 729, in _read_packet
    packet.raise_for_error()
  File "env/lib/python3.10/site-packages/pymysql/protocol.py", line 221, in raise_for_error
    err.raise_mysql_exception(self._data)
  File "env/lib/python3.10/site-packages/pymysql/err.py", line 143, in raise_mysql_exception
    raise errorclass(errno, errval)
pymysql.err.OperationalError: (1698, "Access denied for user '_039cc45dd718bebf'@'localhost'")

2024-06-14 11:06:22,722 ERROR scheduler Exception in Enqueue Events for Site ssd.edofoxerp.com
Traceback (most recent call last):
  File "apps/frappe/frappe/utils/caching.py", line 55, in wrapper
    return frappe.local.request_cache[func][args_key]
KeyError: 5740354900026072187

During handling of the above exception, another exception occurred:

Traceback (most recent call last):
  File "apps/frappe/frappe/utils/caching.py", line 55, in wrapper
    return frappe.local.request_cache[func][args_key]
KeyError: -2601554533826868630

During handling of the above exception, another exception occurred:

Traceback (most recent call last):
  File "apps/frappe/frappe/utils/scheduler.py", line 71, in enqueue_events_for_site
    if is_scheduler_inactive():
  File "apps/frappe/frappe/utils/scheduler.py", line 110, in is_scheduler_inactive
    if is_scheduler_disabled(verbose=verbose):
  File "apps/frappe/frappe/utils/scheduler.py", line 123, in is_scheduler_disabled
    frappe.db.get_single_value("System Settings", "enable_scheduler")
  File "apps/frappe/frappe/database/database.py", line 769, in get_single_value
    val = frappe.qb.engine.get_query(
  File "apps/frappe/frappe/database/query.py", line 515, in get_query
    criterion = self.build_conditions(table, filters, **kwargs)
  File "apps/frappe/frappe/database/query.py", line 371, in build_conditions
    criterion = self.dict_query(filters=filters, table=table, **kwargs)
  File "apps/frappe/frappe/database/query.py", line 330, in dict_query
    _operator = self.OPERATOR_MAP["="]
  File "/usr/lib/python3.10/functools.py", line 981, in __get__
    val = self.func(instance)
  File "apps/frappe/frappe/database/query.py", line 196, in OPERATOR_MAP
    if frappe.get_hooks("filters_config"):
  File "apps/frappe/frappe/__init__.py", line 1496, in get_hooks
    hooks = _dict(_load_app_hooks())
  File "apps/frappe/frappe/utils/caching.py", line 57, in wrapper
    return_val = func(*args, **kwargs)
  File "apps/frappe/frappe/__init__.py", line 1461, in _load_app_hooks
    apps = [app_name] if app_name else get_installed_apps(_ensure_on_bench=True)
  File "apps/frappe/frappe/utils/caching.py", line 57, in wrapper
    return_val = func(*args, **kwargs)
  File "apps/frappe/frappe/__init__.py", line 1417, in get_installed_apps
    installed = json.loads(db.get_global("installed_apps") or "[]")
  File "apps/frappe/frappe/database/database.py", line 961, in get_global
    return self.get_default(key, user)
  File "apps/frappe/frappe/database/database.py", line 965, in get_default
    d = self.get_defaults(key, parent)
  File "apps/frappe/frappe/database/database.py", line 981, in get_defaults
    defaults = frappe.defaults.get_defaults_for(parent)
  File "apps/frappe/frappe/defaults.py", line 239, in get_defaults_for
    frappe.qb.from_(table)
  File "apps/frappe/frappe/query_builder/utils.py", line 76, in execute_query
    return frappe.db.sql(query, params, *args, **kwargs)  # nosemgrep
  File "apps/frappe/frappe/database/database.py", line 200, in sql
    self.connect()
  File "apps/frappe/frappe/database/database.py", line 114, in connect
    self._conn = self.get_connection()
  File "apps/frappe/frappe/database/mariadb/database.py", line 98, in get_connection
    conn = self._get_connection()
  File "apps/frappe/frappe/database/mariadb/database.py", line 104, in _get_connection
    return self.create_connection()
  File "apps/frappe/frappe/database/mariadb/database.py", line 107, in create_connection
    return pymysql.connect(**self.get_connection_settings())
  File "env/lib/python3.10/site-packages/pymysql/connections.py", line 352, in __init__
    self.connect()
  File "env/lib/python3.10/site-packages/pymysql/connections.py", line 636, in connect
    self._request_authentication()
  File "env/lib/python3.10/site-packages/pymysql/connections.py", line 911, in _request_authentication
    auth_packet = self._read_packet()
  File "env/lib/python3.10/site-packages/pymysql/connections.py", line 729, in _read_packet
    packet.raise_for_error()
  File "env/lib/python3.10/site-packages/pymysql/protocol.py", line 221, in raise_for_error
    err.raise_mysql_exception(self._data)
  File "env/lib/python3.10/site-packages/pymysql/err.py", line 143, in raise_mysql_exception
    raise errorclass(errno, errval)
pymysql.err.OperationalError: (1698, "Access denied for user '_039cc45dd718bebf'@'localhost'")

2024-06-14 11:07:22,950 ERROR scheduler Exception in Enqueue Events for Site ssd.edofoxerp.com
Traceback (most recent call last):
  File "apps/frappe/frappe/utils/caching.py", line 55, in wrapper
    return frappe.local.request_cache[func][args_key]
KeyError: 5740354900026072187

During handling of the above exception, another exception occurred:

Traceback (most recent call last):
  File "apps/frappe/frappe/utils/caching.py", line 55, in wrapper
    return frappe.local.request_cache[func][args_key]
KeyError: -2601554533826868630

During handling of the above exception, another exception occurred:

Traceback (most recent call last):
  File "apps/frappe/frappe/utils/scheduler.py", line 71, in enqueue_events_for_site
    if is_scheduler_inactive():
  File "apps/frappe/frappe/utils/scheduler.py", line 110, in is_scheduler_inactive
    if is_scheduler_disabled(verbose=verbose):
  File "apps/frappe/frappe/utils/scheduler.py", line 123, in is_scheduler_disabled
    frappe.db.get_single_value("System Settings", "enable_scheduler")
  File "apps/frappe/frappe/database/database.py", line 769, in get_single_value
    val = frappe.qb.engine.get_query(
  File "apps/frappe/frappe/database/query.py", line 515, in get_query
    criterion = self.build_conditions(table, filters, **kwargs)
  File "apps/frappe/frappe/database/query.py", line 371, in build_conditions
    criterion = self.dict_query(filters=filters, table=table, **kwargs)
  File "apps/frappe/frappe/database/query.py", line 330, in dict_query
    _operator = self.OPERATOR_MAP["="]
  File "/usr/lib/python3.10/functools.py", line 981, in __get__
    val = self.func(instance)
  File "apps/frappe/frappe/database/query.py", line 196, in OPERATOR_MAP
    if frappe.get_hooks("filters_config"):
  File "apps/frappe/frappe/__init__.py", line 1496, in get_hooks
    hooks = _dict(_load_app_hooks())
  File "apps/frappe/frappe/utils/caching.py", line 57, in wrapper
    return_val = func(*args, **kwargs)
  File "apps/frappe/frappe/__init__.py", line 1461, in _load_app_hooks
    apps = [app_name] if app_name else get_installed_apps(_ensure_on_bench=True)
  File "apps/frappe/frappe/utils/caching.py", line 57, in wrapper
    return_val = func(*args, **kwargs)
  File "apps/frappe/frappe/__init__.py", line 1417, in get_installed_apps
    installed = json.loads(db.get_global("installed_apps") or "[]")
  File "apps/frappe/frappe/database/database.py", line 961, in get_global
    return self.get_default(key, user)
  File "apps/frappe/frappe/database/database.py", line 965, in get_default
    d = self.get_defaults(key, parent)
  File "apps/frappe/frappe/database/database.py", line 981, in get_defaults
    defaults = frappe.defaults.get_defaults_for(parent)
  File "apps/frappe/frappe/defaults.py", line 239, in get_defaults_for
    frappe.qb.from_(table)
  File "apps/frappe/frappe/query_builder/utils.py", line 76, in execute_query
    return frappe.db.sql(query, params, *args, **kwargs)  # nosemgrep
  File "apps/frappe/frappe/database/database.py", line 200, in sql
    self.connect()
  File "apps/frappe/frappe/database/database.py", line 114, in connect
    self._conn = self.get_connection()
  File "apps/frappe/frappe/database/mariadb/database.py", line 98, in get_connection
    conn = self._get_connection()
  File "apps/frappe/frappe/database/mariadb/database.py", line 104, in _get_connection
    return self.create_connection()
  File "apps/frappe/frappe/database/mariadb/database.py", line 107, in create_connection
    return pymysql.connect(**self.get_connection_settings())
  File "env/lib/python3.10/site-packages/pymysql/connections.py", line 352, in __init__
    self.connect()
  File "env/lib/python3.10/site-packages/pymysql/connections.py", line 636, in connect
    self._request_authentication()
  File "env/lib/python3.10/site-packages/pymysql/connections.py", line 911, in _request_authentication
    auth_packet = self._read_packet()
  File "env/lib/python3.10/site-packages/pymysql/connections.py", line 729, in _read_packet
    packet.raise_for_error()
  File "env/lib/python3.10/site-packages/pymysql/protocol.py", line 221, in raise_for_error
    err.raise_mysql_exception(self._data)
  File "env/lib/python3.10/site-packages/pymysql/err.py", line 143, in raise_mysql_exception
    raise errorclass(errno, errval)
pymysql.err.OperationalError: (1698, "Access denied for user '_039cc45dd718bebf'@'localhost'")

2024-06-14 11:08:23,251 ERROR scheduler Exception in Enqueue Events for Site ssd.edofoxerp.com
Traceback (most recent call last):
  File "apps/frappe/frappe/utils/caching.py", line 55, in wrapper
    return frappe.local.request_cache[func][args_key]
KeyError: 5740354900026072187

During handling of the above exception, another exception occurred:

Traceback (most recent call last):
  File "apps/frappe/frappe/utils/caching.py", line 55, in wrapper
    return frappe.local.request_cache[func][args_key]
KeyError: -2601554533826868630

During handling of the above exception, another exception occurred:

Traceback (most recent call last):
  File "apps/frappe/frappe/utils/scheduler.py", line 71, in enqueue_events_for_site
    if is_scheduler_inactive():
  File "apps/frappe/frappe/utils/scheduler.py", line 110, in is_scheduler_inactive
    if is_scheduler_disabled(verbose=verbose):
  File "apps/frappe/frappe/utils/scheduler.py", line 123, in is_scheduler_disabled
    frappe.db.get_single_value("System Settings", "enable_scheduler")
  File "apps/frappe/frappe/database/database.py", line 769, in get_single_value
    val = frappe.qb.engine.get_query(
  File "apps/frappe/frappe/database/query.py", line 515, in get_query
    criterion = self.build_conditions(table, filters, **kwargs)
  File "apps/frappe/frappe/database/query.py", line 371, in build_conditions
    criterion = self.dict_query(filters=filters, table=table, **kwargs)
  File "apps/frappe/frappe/database/query.py", line 330, in dict_query
    _operator = self.OPERATOR_MAP["="]
  File "/usr/lib/python3.10/functools.py", line 981, in __get__
    val = self.func(instance)
  File "apps/frappe/frappe/database/query.py", line 196, in OPERATOR_MAP
    if frappe.get_hooks("filters_config"):
  File "apps/frappe/frappe/__init__.py", line 1496, in get_hooks
    hooks = _dict(_load_app_hooks())
  File "apps/frappe/frappe/utils/caching.py", line 57, in wrapper
    return_val = func(*args, **kwargs)
  File "apps/frappe/frappe/__init__.py", line 1461, in _load_app_hooks
    apps = [app_name] if app_name else get_installed_apps(_ensure_on_bench=True)
  File "apps/frappe/frappe/utils/caching.py", line 57, in wrapper
    return_val = func(*args, **kwargs)
  File "apps/frappe/frappe/__init__.py", line 1417, in get_installed_apps
    installed = json.loads(db.get_global("installed_apps") or "[]")
  File "apps/frappe/frappe/database/database.py", line 961, in get_global
    return self.get_default(key, user)
  File "apps/frappe/frappe/database/database.py", line 965, in get_default
    d = self.get_defaults(key, parent)
  File "apps/frappe/frappe/database/database.py", line 981, in get_defaults
    defaults = frappe.defaults.get_defaults_for(parent)
  File "apps/frappe/frappe/defaults.py", line 239, in get_defaults_for
    frappe.qb.from_(table)
  File "apps/frappe/frappe/query_builder/utils.py", line 76, in execute_query
    return frappe.db.sql(query, params, *args, **kwargs)  # nosemgrep
  File "apps/frappe/frappe/database/database.py", line 200, in sql
    self.connect()
  File "apps/frappe/frappe/database/database.py", line 114, in connect
    self._conn = self.get_connection()
  File "apps/frappe/frappe/database/mariadb/database.py", line 98, in get_connection
    conn = self._get_connection()
  File "apps/frappe/frappe/database/mariadb/database.py", line 104, in _get_connection
    return self.create_connection()
  File "apps/frappe/frappe/database/mariadb/database.py", line 107, in create_connection
    return pymysql.connect(**self.get_connection_settings())
  File "env/lib/python3.10/site-packages/pymysql/connections.py", line 352, in __init__
    self.connect()
  File "env/lib/python3.10/site-packages/pymysql/connections.py", line 636, in connect
    self._request_authentication()
  File "env/lib/python3.10/site-packages/pymysql/connections.py", line 911, in _request_authentication
    auth_packet = self._read_packet()
  File "env/lib/python3.10/site-packages/pymysql/connections.py", line 729, in _read_packet
    packet.raise_for_error()
  File "env/lib/python3.10/site-packages/pymysql/protocol.py", line 221, in raise_for_error
    err.raise_mysql_exception(self._data)
  File "env/lib/python3.10/site-packages/pymysql/err.py", line 143, in raise_mysql_exception
    raise errorclass(errno, errval)
pymysql.err.OperationalError: (1698, "Access denied for user '_039cc45dd718bebf'@'localhost'")

2024-06-14 11:09:23,499 ERROR scheduler Exception in Enqueue Events for Site ssd.edofoxerp.com
Traceback (most recent call last):
  File "apps/frappe/frappe/utils/caching.py", line 55, in wrapper
    return frappe.local.request_cache[func][args_key]
KeyError: 5740354900026072187

During handling of the above exception, another exception occurred:

Traceback (most recent call last):
  File "apps/frappe/frappe/utils/caching.py", line 55, in wrapper
    return frappe.local.request_cache[func][args_key]
KeyError: -2601554533826868630

During handling of the above exception, another exception occurred:

Traceback (most recent call last):
  File "apps/frappe/frappe/utils/scheduler.py", line 71, in enqueue_events_for_site
    if is_scheduler_inactive():
  File "apps/frappe/frappe/utils/scheduler.py", line 110, in is_scheduler_inactive
    if is_scheduler_disabled(verbose=verbose):
  File "apps/frappe/frappe/utils/scheduler.py", line 123, in is_scheduler_disabled
    frappe.db.get_single_value("System Settings", "enable_scheduler")
  File "apps/frappe/frappe/database/database.py", line 769, in get_single_value
    val = frappe.qb.engine.get_query(
  File "apps/frappe/frappe/database/query.py", line 515, in get_query
    criterion = self.build_conditions(table, filters, **kwargs)
  File "apps/frappe/frappe/database/query.py", line 371, in build_conditions
    criterion = self.dict_query(filters=filters, table=table, **kwargs)
  File "apps/frappe/frappe/database/query.py", line 330, in dict_query
    _operator = self.OPERATOR_MAP["="]
  File "/usr/lib/python3.10/functools.py", line 981, in __get__
    val = self.func(instance)
  File "apps/frappe/frappe/database/query.py", line 196, in OPERATOR_MAP
    if frappe.get_hooks("filters_config"):
  File "apps/frappe/frappe/__init__.py", line 1496, in get_hooks
    hooks = _dict(_load_app_hooks())
  File "apps/frappe/frappe/utils/caching.py", line 57, in wrapper
    return_val = func(*args, **kwargs)
  File "apps/frappe/frappe/__init__.py", line 1461, in _load_app_hooks
    apps = [app_name] if app_name else get_installed_apps(_ensure_on_bench=True)
  File "apps/frappe/frappe/utils/caching.py", line 57, in wrapper
    return_val = func(*args, **kwargs)
  File "apps/frappe/frappe/__init__.py", line 1417, in get_installed_apps
    installed = json.loads(db.get_global("installed_apps") or "[]")
  File "apps/frappe/frappe/database/database.py", line 961, in get_global
    return self.get_default(key, user)
  File "apps/frappe/frappe/database/database.py", line 965, in get_default
    d = self.get_defaults(key, parent)
  File "apps/frappe/frappe/database/database.py", line 981, in get_defaults
    defaults = frappe.defaults.get_defaults_for(parent)
  File "apps/frappe/frappe/defaults.py", line 239, in get_defaults_for
    frappe.qb.from_(table)
  File "apps/frappe/frappe/query_builder/utils.py", line 76, in execute_query
    return frappe.db.sql(query, params, *args, **kwargs)  # nosemgrep
  File "apps/frappe/frappe/database/database.py", line 200, in sql
    self.connect()
  File "apps/frappe/frappe/database/database.py", line 114, in connect
    self._conn = self.get_connection()
  File "apps/frappe/frappe/database/mariadb/database.py", line 98, in get_connection
    conn = self._get_connection()
  File "apps/frappe/frappe/database/mariadb/database.py", line 104, in _get_connection
    return self.create_connection()
  File "apps/frappe/frappe/database/mariadb/database.py", line 107, in create_connection
    return pymysql.connect(**self.get_connection_settings())
  File "env/lib/python3.10/site-packages/pymysql/connections.py", line 352, in __init__
    self.connect()
  File "env/lib/python3.10/site-packages/pymysql/connections.py", line 636, in connect
    self._request_authentication()
  File "env/lib/python3.10/site-packages/pymysql/connections.py", line 911, in _request_authentication
    auth_packet = self._read_packet()
  File "env/lib/python3.10/site-packages/pymysql/connections.py", line 729, in _read_packet
    packet.raise_for_error()
  File "env/lib/python3.10/site-packages/pymysql/protocol.py", line 221, in raise_for_error
    err.raise_mysql_exception(self._data)
  File "env/lib/python3.10/site-packages/pymysql/err.py", line 143, in raise_mysql_exception
    raise errorclass(errno, errval)
pymysql.err.OperationalError: (1698, "Access denied for user '_039cc45dd718bebf'@'localhost'")

2024-06-14 11:10:23,724 ERROR scheduler Exception in Enqueue Events for Site ssd.edofoxerp.com
Traceback (most recent call last):
  File "apps/frappe/frappe/utils/caching.py", line 55, in wrapper
    return frappe.local.request_cache[func][args_key]
KeyError: 5740354900026072187

During handling of the above exception, another exception occurred:

Traceback (most recent call last):
  File "apps/frappe/frappe/utils/caching.py", line 55, in wrapper
    return frappe.local.request_cache[func][args_key]
KeyError: -2601554533826868630

During handling of the above exception, another exception occurred:

Traceback (most recent call last):
  File "apps/frappe/frappe/utils/scheduler.py", line 71, in enqueue_events_for_site
    if is_scheduler_inactive():
  File "apps/frappe/frappe/utils/scheduler.py", line 110, in is_scheduler_inactive
    if is_scheduler_disabled(verbose=verbose):
  File "apps/frappe/frappe/utils/scheduler.py", line 123, in is_scheduler_disabled
    frappe.db.get_single_value("System Settings", "enable_scheduler")
  File "apps/frappe/frappe/database/database.py", line 769, in get_single_value
    val = frappe.qb.engine.get_query(
  File "apps/frappe/frappe/database/query.py", line 515, in get_query
    criterion = self.build_conditions(table, filters, **kwargs)
  File "apps/frappe/frappe/database/query.py", line 371, in build_conditions
    criterion = self.dict_query(filters=filters, table=table, **kwargs)
  File "apps/frappe/frappe/database/query.py", line 330, in dict_query
    _operator = self.OPERATOR_MAP["="]
  File "/usr/lib/python3.10/functools.py", line 981, in __get__
    val = self.func(instance)
  File "apps/frappe/frappe/database/query.py", line 196, in OPERATOR_MAP
    if frappe.get_hooks("filters_config"):
  File "apps/frappe/frappe/__init__.py", line 1496, in get_hooks
    hooks = _dict(_load_app_hooks())
  File "apps/frappe/frappe/utils/caching.py", line 57, in wrapper
    return_val = func(*args, **kwargs)
  File "apps/frappe/frappe/__init__.py", line 1461, in _load_app_hooks
    apps = [app_name] if app_name else get_installed_apps(_ensure_on_bench=True)
  File "apps/frappe/frappe/utils/caching.py", line 57, in wrapper
    return_val = func(*args, **kwargs)
  File "apps/frappe/frappe/__init__.py", line 1417, in get_installed_apps
    installed = json.loads(db.get_global("installed_apps") or "[]")
  File "apps/frappe/frappe/database/database.py", line 961, in get_global
    return self.get_default(key, user)
  File "apps/frappe/frappe/database/database.py", line 965, in get_default
    d = self.get_defaults(key, parent)
  File "apps/frappe/frappe/database/database.py", line 981, in get_defaults
    defaults = frappe.defaults.get_defaults_for(parent)
  File "apps/frappe/frappe/defaults.py", line 239, in get_defaults_for
    frappe.qb.from_(table)
  File "apps/frappe/frappe/query_builder/utils.py", line 76, in execute_query
    return frappe.db.sql(query, params, *args, **kwargs)  # nosemgrep
  File "apps/frappe/frappe/database/database.py", line 200, in sql
    self.connect()
  File "apps/frappe/frappe/database/database.py", line 114, in connect
    self._conn = self.get_connection()
  File "apps/frappe/frappe/database/mariadb/database.py", line 98, in get_connection
    conn = self._get_connection()
  File "apps/frappe/frappe/database/mariadb/database.py", line 104, in _get_connection
    return self.create_connection()
  File "apps/frappe/frappe/database/mariadb/database.py", line 107, in create_connection
    return pymysql.connect(**self.get_connection_settings())
  File "env/lib/python3.10/site-packages/pymysql/connections.py", line 352, in __init__
    self.connect()
  File "env/lib/python3.10/site-packages/pymysql/connections.py", line 636, in connect
    self._request_authentication()
  File "env/lib/python3.10/site-packages/pymysql/connections.py", line 911, in _request_authentication
    auth_packet = self._read_packet()
  File "env/lib/python3.10/site-packages/pymysql/connections.py", line 729, in _read_packet
    packet.raise_for_error()
  File "env/lib/python3.10/site-packages/pymysql/protocol.py", line 221, in raise_for_error
    err.raise_mysql_exception(self._data)
  File "env/lib/python3.10/site-packages/pymysql/err.py", line 143, in raise_mysql_exception
    raise errorclass(errno, errval)
pymysql.err.OperationalError: (1698, "Access denied for user '_039cc45dd718bebf'@'localhost'")

